Workbook

Sheet For Creation
A1: Full name | B1: First name | C1: Last name | D1: Username | E1: Password | F1: Group | G1: Position | H1: Business Center | I1: Status
A2: Yasona, Rathia Joyce | B2: Rathia Joyce | C2: Yasona | D2: rdyasona@chookstogoinc.com.ph | E2: Bounty2025 | F2: Retail | G2: Regional Head | H2: South Luzon
A3: Librando , Michael Angelo | B3: Michael Angelo | C3: Librando | D3: mclibrando@chookstogoinc.com.ph | E3: Bounty2025 | F3: Retail | G3: Regional Head | H3: North and Central Luzon
A4: Navarro, Dominico | B4: Dominico | C4: Navarro | D4: dbnavarro@chookstogoinc.com.ph | E4: Bounty2025 | F4: Retail | G4: Regional Head | H4: Metro Manila
A5: Zapata, Sonny | B5: Sonny | C5: Zapata | D5: sczapata@bounty.com.ph | E5: Bounty2025 | F5: Retail | G5: Business Center Head | H5: Zamboanga
A6: Siapno, Cedric | B6: Cedric | C6: Siapno | D6: cgsiapno@bounty.com.ph | E6: Bounty2025 | F6: Retail | G6: Store Specialist/s | H6: Zamboanga
A7: Serito, Jessie | B7: Jessie | C7: Serito | D7: jeserito@chookstogoinc.com.ph | E7: Bounty2025 | F7: Retail | G7: Mindanao Engineering Head | H7: Zamboanga
A8: Sanchez, Larry | B8: Larry | C8: Sanchez | D8: lhsanchez@chookstogoinc.com.ph | E8: Bounty2025 | F8: Retail | G8: Maintenance Supervisor/s | H8: Zamboanga
A9: Perez, Edward Jeko | B9: Edward Jeko | C9: Perez | D9: epperez@chookstogoinc.com.ph | E9: Bounty2025 | F9: Retail | G9: Business Center Head | H9: Tacloban
A10: Estoque, Errol Michael | B10: Errol Michael | C10: Estoque | D10: epestoque@bounty.com.ph | E10: Bounty2025 | F10: Retail | G10: Area Head/s | H10: Tacloban
A11: Armada, Richelle | B11: Richelle | C11: Armada | D11: rlarmada@bounty.com.ph | E11: Bounty2025 | F11: Retail | G11: Store Specialist/s | H11: Tacloban
A12: Efren, Gertrudes | B12: Gertrudes | C12: Efren | D12: grefren@bounty.com.ph | E12: Bounty2025 | F12: Retail | G12: Store Specialist/s | H12: Tacloban
A13: Andrada, Giovanni | B13: Giovanni | C13: Andrada | D13: glandrada@bounty.com.ph | E13: Bounty2025 | F13: Retail | G13: Store Specialist/s | H13: Tacloban
... A170: Benetua, Mark Almar | B170: Mark Almar | C170: Benetua | D170: mtbenetua@chookstogoinc.com.ph | E170: Bounty2025 | F170: IT Hardware | G170: IT Tech/ Coordinator | H170: Iloilo and Roxas

Sheet 1st Batch
A1: Full name | B1: First name | C1: Last name | D1: Username | E1: Password | F1: Group | G1: Position | H1: Business Center | I1: Status
A2: Rodriguez, Emilie | B2: Emilie | C2: Rodriguez | D2: eprodriguez@chookstogoinc.com.ph | E2: Bounty2025 | F2: Retail | G2: Business Center Head | H2: Metro Manila | I2: Done | J2: =IF(COUNTIF($D$2:$D$187, D2)>1, "Duplicate", "Unique") -> Unique
A3: Abejero, Justine Micaela | B3: Justine Micaela | C3: Abejero | D3: jlabejero@chookstogoinc.com.ph | E3: Bounty2025 | F3: Retail | G3: Area Head | H3: Metro Manila | I3: Done | J3: =IF(COUNTIF($D$2:$D$187, D3)>1, "Duplicate", "Unique") -> Unique
A4: Poblete, Essjay | B4: Essjay | C4: Poblete | D4: espoblete@chookstogoinc.com.ph | E4: Bounty2025 | F4: Retail | G4: Area Head | H4: Metro Manila | I4: Done | J4: =IF(COUNTIF($D$2:$D$187, D4)>1, "Duplicate", "Unique") -> Unique
A5: Peduche, Demetrio | B5: Demetrio | C5: Peduche | D5: dcpeduche@chookstogoinc.com.ph | E5: Bounty2025 | F5: Retail | G5: Luzon Engineering Head | H5: Luzon | I5: Done | J5: =IF(COUNTIF($D$2:$D$187, D5)>1, "Duplicate", "Unique") -> Unique
A6: Garrovillas, Adrian | B6: Adrian | C6: Garrovillas | D6: argarrovillas@chookstogoinc.com.ph | E6: Bounty2025 | F6: Retail | G6: Maintenance Supervisor | H6: Metro Manila | I6: Done | J6: =IF(COUNTIF($D$2:$D$187, D6)>1, "Duplicate", "Unique") -> Unique
A7: Guanlao, Cristina | B7: Cristina | C7: Guanlao | D7: cpguanlao@chookstogoinc.com.ph | E7: Bounty2025 | F7: Retail | G7: Admin | H7: Metro Manila | I7: Done | J7: =IF(COUNTIF($D$2:$D$187, D7)>1, "Duplicate", "Unique") -> Unique
A8: Aguilus, Artessa | B8: Artessa | C8: Aguilus | D8: acaguilus@chookstogoinc.com.ph | E8: Bounty2025 | F8: Retail | G8: Admin | H8: Central Luzon | I8: Done | J8: =IF(COUNTIF($D$2:$D$187, D8)>1, "Duplicate", "Unique") -> Unique
A9: Mendoza, Evelyn | B9: Evelyn | C9: Mendoza | D9: esmendoza@chookstogoinc.com.ph | E9: Bounty2025 | F9: Retail | G9: Business Center Head | H9: Central Luzon | I9: Done | J9: =IF(COUNTIF($D$2:$D$187, D9)>1, "Duplicate", "Unique") -> Unique
A10: Dela Cruz, Glaiza | B10: Glaiza | C10: Dela Cruz | D10: gldelacruz@chookstogoinc.com.ph | E10: Bounty2025 | F10: Retail | G10: Area Head | H10: Central Luzon | I10: Done | J10: =IF(COUNTIF($D$2:$D$187, D10)>1, "Duplicate", "Unique") -> Unique
A11: Nazal, Arnel | B11: Arnel | C11: Nazal | D11: apnazal@chookstogoinc.com.ph | E11: Bounty2025 | F11: Retail | G11: Area Head | H11: Central Luzon | I11: Done | J11: =IF(COUNTIF($D$2:$D$187, D11)>1, "Duplicate", "Unique") -> Unique
A12: Martinez, Tricia Faye | B12: Tricia Faye | C12: Martinez | D12: tsmartinez@chookstogoinc.com.ph | E12: Bounty2025 | F12: Retail | G12: Maintenance Supervisor | H12: Central Luzon | I12: Done | J12: =IF(COUNTIF($D$2:$D$187, D12)>1, "Duplicate", "Unique") -> Unique
A13: Carrera, Arnold Sharwin | B13: Arnold Sharwin | C13: Carrera | D13: amcarrera@chookstogoinc.com.ph | E13: Bounty2025 | F13: Retail | G13: Business Center Head | H13: Ilocos | I13: Done | J13: =IF(COUNTIF($D$2:$D$187, D13)>1, "Duplicate", "Unique") -> Unique
... A29: Maligaya, Bricks Keno | B29: Bricks Keno | C29: Maligaya | D29: btmaligaya@chookstogoinc.com.ph | E29: Bounty2025 | F29: Retail | G29: Maintenance Supervisor | H29: STAG | I29: Done | J29: =IF(COUNTIF($D$2:$D$187, D29)>1, "Duplicate", "Unique") -> Unique
A30: Yasona, Rathia Joyce | B30: Rathia Joyce | C30: Yasona | D30: rdyasona@chookstogoinc.com.ph | E30: Bounty2025 | F30: Retail | G30: Regional Head | H30: South Luzon | J30: =IF(COUNTIF($D$2:$D$187, D30)>1, "Duplicate", "Unique") -> Unique
A31: Librando , Michael Angelo | B31: Michael Angelo | C31: Librando | D31: mclibrando@chookstogoinc.com.ph | E31: Bounty2025 | F31: Retail | G31: Regional Head | H31: North and Central Luzon | J31: =IF(COUNTIF($D$2:$D$187, D31)>1, "Duplicate", "Unique") -> Unique
A32: Navarro, Dominico | B32: Dominico | C32: Navarro | D32: dbnavarro@chookstogoinc.com.ph | E32: Bounty2025 | F32: Retail | G32: Regional Head | H32: Metro Manila | J32: =IF(COUNTIF($D$2:$D$187, D32)>1, "Duplicate", "Unique") -> Unique
A33: Zapata, Sonny | B33: Sonny | C33: Zapata | D33: sczapata@bounty.com.ph | E33: Bounty2025 | F33: Retail | G33: Business Center Head | H33: Zamboanga | J33: =IF(COUNTIF($D$2:$D$187, D33)>1, "Duplicate", "Unique") -> Unique
A34: Siapno, Cedric | B34: Cedric | C34: Siapno | D34: cgsiapno@bounty.com.ph | E34: Bounty2025 | F34: Retail | G34: Store Specialist/s | H34: Zamboanga | J34: =IF(COUNTIF($D$2:$D$187, D34)>1, "Duplicate", "Unique") -> Unique
A35: Serito, Jessie | B35: Jessie | C35: Serito | D35: jeserito@chookstogoinc.com.ph | E35: Bounty2025 | F35: Retail | G35: Mindanao Engineering Head | H35: Zamboanga | J35: =IF(COUNTIF($D$2:$D$187, D35)>1, "Duplicate", "Unique") -> Unique
A36: Sanchez, Larry | B36: Larry | C36: Sanchez | D36: lhsanchez@chookstogoinc.com.ph | E36: Bounty2025 | F36: Retail | G36: Maintenance Supervisor/s | H36: Zamboanga | J36: =IF(COUNTIF($D$2:$D$187, D36)>1, "Duplicate", "Unique") -> Unique
A37: Perez, Edward Jeko | B37: Edward Jeko | C37: Perez | D37: epperez@chookstogoinc.com.ph | E37: Bounty2025 | F37: Retail | G37: Business Center Head | H37: Tacloban | J37: =IF(COUNTIF($D$2:$D$187, D37)>1, "Duplicate", "Unique") -> Unique
A38: Estoque, Errol Michael | B38: Errol Michael | C38: Estoque | D38: epestoque@bounty.com.ph | E38: Bounty2025 | F38: Retail | G38: Area Head/s | H38: Tacloban | J38: =IF(COUNTIF($D$2:$D$187, D38)>1, "Duplicate", "Unique") -> Unique
A39: Armada, Richelle | B39: Richelle | C39: Armada | D39: rlarmada@bounty.com.ph | E39: Bounty2025 | F39: Retail | G39: Store Specialist/s | H39: Tacloban | J39: =IF(COUNTIF($D$2:$D$187, D39)>1, "Duplicate", "Unique") -> Unique
A40: Efren, Gertrudes | B40: Gertrudes | C40: Efren | D40: grefren@bounty.com.ph | E40: Bounty2025 | F40: Retail | G40: Store Specialist/s | H40: Tacloban | J40: =IF(COUNTIF($D$2:$D$187, D40)>1, "Duplicate", "Unique") -> Unique
A41: Andrada, Giovanni | B41: Giovanni | C41: Andrada | D41: glandrada@bounty.com.ph | E41: Bounty2025 | F41: Retail | G41: Store Specialist/s | H41: Tacloban | J41: =IF(COUNTIF($D$2:$D$187, D41)>1, "Duplicate", "Unique") -> Unique
... A83: Castor, Robert Franci | B83: Robert Francis | C83: Castor | D83: rccastor@chookstogoinc.com.ph | E83: Bounty2025 | F83: Retail | G83: Maintenance Supervisor/s | H83: Iloilo | J83: =IF(COUNTIF($D$2:$D$187, D83)>1, "Duplicate", "Unique") -> Unique
A84: Nuay, Mia Fe | B84: Mia Fe | C84: Nuay | E84: Bounty2025 | F84: Retail | G84: Store Specialist | H84: Bacolod | J84: =IF(COUNTIF('1st Batch'!B:B, H84)>0, "Duplicate", "Unique") -> Unique
A85: Buga-ay, Bengie | B85: Bengie | C85: Buga-ay | D85: bmbugaay@chookstogoinc.com.ph | E85: Bounty2025 | F85: Retail | G85: Store Technician Supervisor | H85: Bacolod | J85: =IF(COUNTIF('1st Batch'!B:B, H85)>0, "Duplicate", "Unique") -> Unique
A86: Patindol, Narciso | B86: Narciso | C86: Patindol | E86: Bounty2025 | F86: Retail | G86: Store Senior Specialist | H86: Bicol | J86: =IF(COUNTIF('1st Batch'!B:B, H86)>0, "Duplicate", "Unique") -> Unique
A87: Zantua, Santiago | B87: Santiago | C87: Zantua | D87: srzantua@bounty.com.ph | E87: Bounty2025 | F87: Retail | G87: Store Senior Specialist | H87: Bicol | J87: =IF(COUNTIF('1st Batch'!B:B, H87)>0, "Duplicate", "Unique") -> Unique
A88: Robles, Rachell Maritoni | B88: Rachell Maritoni | C88: Robles | D88: rgrobles@bounty.com.ph | E88: Bounty2025 | F88: Retail | G88: Store Specialist | H88: Bicol | J88: =IF(COUNTIF('1st Batch'!B:B, H88)>0, "Duplicate", "Unique") -> Unique
A89: Saludes, Samson | B89: Samson | C89: Saludes | E89: Bounty2025 | F89: Retail | G89: Store Technician | H89: Bicol | J89: =IF(COUNTIF('1st Batch'!B:B, H89)>0, "Duplicate", "Unique") -> Unique
A90: Ayao, Rommel | B90: Rommel | C90: Ayao | E90: Bounty2025 | F90: Retail | G90: Store Technician | H90: Butuan | J90: =IF(COUNTIF('1st Batch'!B:B, H90)>0, "Duplicate", "Unique") -> Unique
A91: Andal, Amebert | B91: Amebert | C91: Andal | D91: arandales@chookstogoinc.com.ph | E91: Bounty2025 | F91: Retail | G91: Store Technician | H91: Cagayan de Oro | J91: =IF(COUNTIF('1st Batch'!B:B, H91)>0, "Duplicate", "Unique") -> Unique
A92: Leparto, Kim Justine | B92: Kim Justine | C92: Leparto | E92: Bounty2025 | F92: Retail | G92: Store Technician | H92: Cagayan de Oro | J92: =IF(COUNTIF('1st Batch'!B:B, H92)>0, "Duplicate", "Unique") -> Unique
A93: Tan, Noel Brayan | B93: Noel Brayan | C93: Tan | D93: nltan@bounty.com.ph | E93: Bounty2025 | F93: Retail | G93: Store Technician | H93: Cebu | J93: =IF(COUNTIF('1st Batch'!B:B, H93)>0, "Duplicate", "Unique") -> Unique
A94: Lacio, Alner | B94: Alner | C94: Lacio | E94: Bounty2025 | F94: Retail | G94: Store Technician | H94: Cebu | J94: =IF(COUNTIF('1st Batch'!B:B, H94)>0, "Duplicate", "Unique") -> Unique
A95: Magsino, Rubenor | B95: Rubenor | C95: Magsino | D95: rdmagsino@bounty.com.ph | E95: Bounty2025 | F95: Retail | G95: Store Senior Specialist | H95: Central Luzon | J95: =IF(COUNTIF('1st Batch'!B:B, H95)>0, "Duplicate", "Unique") -> Unique
A96: Perez, Ramon Christopher | B96: Ramon Christopher | C96: Perez | D96: rbperez@bounty.com.ph | E96: Bounty2025 | F96: Retail | G96: Store Senior Specialist | H96: Pangasinan | J96: =IF(COUNTIF('1st Batch'!B:B, H96)>0, "Duplicate", "Unique") -> Unique
...

Sheet Store Specialist
A1: No. | B1: Company Code | C1: Tarkie Assignee | D1: Firstname | E1: Lastname | F1: Group | G1: Business Center | H1: Position | I1: Username | J1: Password | K1: Status vs 1st Batch
A2: 1 | B2: 89HKJSYG | C2: Ibugan, Elmer | D2: Elmer | E2: Ibugan | F2: Retail | G2: Bacolod | H2: Store Specialist | I2: egibugan@bounty.com.ph | J2: Bounty2025 | K2: =IF(COUNTIF('1st Batch'!D:D, I2)>0, "Duplicate", "Unique") -> Duplicate
A3: 2 | B3: 89HKJSYG | C3: Nuay, Mia Fe | D3: Mia Fe | E3: Nuay | F3: Retail | G3: Bacolod | H3: Store Specialist | I3: Nuay_MiaFe | J3: Bounty2025 | K3: =IF(COUNTIF('1st Batch'!D:D, I3)>0, "Duplicate", "Unique") -> Unique
A4: 3 | B4: 89HKJSYG | C4: Lamis, Joshua | D4: Joshua | E4: Lamis | F4: Retail | G4: Bacolod | H4: Store Specialist | I4: jvlamis@bounty.com.ph | J4: Bounty2025 | K4: =IF(COUNTIF('1st Batch'!D:D, I4)>0, "Duplicate", "Unique") -> Duplicate
A5: 4 | B5: 89HKJSYG | C5: Buga-ay, Bengie | D5: Bengie | E5: Buga-ay | F5: Retail | G5: Bacolod | H5: Store Technician Supervisor | I5: bmbugaay@chookstogoinc.com.ph | J5: Bounty2025 | K5: =IF(COUNTIF('1st Batch'!D:D, I5)>0, "Duplicate", "Unique") -> Duplicate
A6: 5 | B6: 89HKJSYG | C6: Amoto, Honey Anne | D6: Honey Anne | E6: Amoto | F6: Retail | G6: Bacolod | H6: Store Specialist | I6: hmamoto@bounty.com.ph | J6: Bounty2025 | K6: =IF(COUNTIF('1st Batch'!D:D, I6)>0, "Duplicate", "Unique") -> Duplicate
A7: 6 | B7: 89HKJSYG | C7: Patindol, Narciso | D7: Narciso | E7: Patindol | F7: Retail | G7: Bicol | H7: Store Senior Specialist | I7: Patindol_Narciso | J7: Bounty2025 | K7: =IF(COUNTIF('1st Batch'!D:D, I7)>0, "Duplicate", "Unique") -> Unique
A8: 7 | B8: 89HKJSYG | C8: Zantua, Santiago | D8: Santiago | E8: Zantua | F8: Retail | G8: Bicol | H8: Store Senior Specialist | I8: srzantua@bounty.com.ph | J8: Bounty2025 | K8: =IF(COUNTIF('1st Batch'!D:D, I8)>0, "Duplicate", "Unique") -> Duplicate
A9: 8 | B9: 89HKJSYG | C9: Robles, Rachell Maritoni | D9: Rachell Maritoni | E9: Robles | F9: Retail | G9: Bicol | H9: Store Specialist | I9: rgrobles@bounty.com.ph | J9: Bounty2025 | K9: =IF(COUNTIF('1st Batch'!D:D, I9)>0, "Duplicate", "Unique") -> Duplicate
A10: 9 | B10: 89HKJSYG | C10: Saludes, Samson | D10: Samson | E10: Saludes | F10: Retail | G10: Bicol | H10: Store Technician | I10: Saludes_Samson | J10: Bounty2025 | K10: =IF(COUNTIF('1st Batch'!D:D, I10)>0, "Duplicate", "Unique") -> Unique
A11: 10 | B11: 89HKJSYG | C11: Gavica, Mary Linette | D11: Mary Linette | E11: Gavica | F11: Retail | G11: Bicol | H11: Store Technician Supervisor | I11: mbgavica@chookstogoinc.com.ph | J11: Bounty2025 | K11: =IF(COUNTIF('1st Batch'!D:D, I11)>0, "Duplicate", "Unique") -> Duplicate
A12: 11 | B12: 89HKJSYG | C12: Ayao, Rommel | D12: Rommel | E12: Ayao | F12: Retail | G12: Butuan | H12: Store Technician | I12: Ayao_Rommel | J12: Bounty2025 | K12: =IF(COUNTIF('1st Batch'!D:D, I12)>0, "Duplicate", "Unique") -> Unique
A13: 12 | B13: 89HKJSYG | C13: Espinosa, Mark Gerald | D13: Mark Gerald | E13: Espinosa | F13: Retail | G13: Cagayan De Oro | H13: Store Specialist | I13: maespinosa@bounty.com.ph | J13: Bounty2025 | K13: =IF(COUNTIF('1st Batch'!D:D, I13)>0, "Duplicate", "Unique") -> Duplicate
... A139: 138 | B139: 89HKJSYG | C139: Ephraim Rodriguez | D139: Ephraim | E139: Rodriguez | F139: Retail | G139: Central Luzon | H139: Store Technician | I139: Rodriguez_Ephraim | J139: Bounty2025 | K139: =IF(COUNTIF('1st Batch'!D:D, I139)>0, "Duplicate", "Unique") -> Unique

Sheet IT Tech
A1: IT Personnel | B1: Operational Base | C1: Area of coverage | D1: Email | E1: Username | F1: Password
A2: Philip James Manuntag | B2: Isabela | C2: Provincial Luzon (Isabela, Pangasinan, and Ilocos) | D2: pcmanuntag@chookstogoinc.com.ph | E2: pcmanuntag@chookstogoinc.com.ph | F2: Bounty2025
A3: Jonathan Cayabyab | B3: Pangasinan | C3: Pangasinan and Ilocos | D3: jscayabyab@chookstogoinc.com.ph | E3: jscayabyab@chookstogoinc.com.ph | F3: Bounty2025
A4: John Jordan Celebre | B4: BGC | C4: MMCL and NCR | D4: jbcelebre@chookstogoinc.com.ph | E4: jbcelebre@chookstogoinc.com.ph | F4: Bounty2025
A5: John Earl Amores | B5: BGC | C5: BGC Metro Manila and Caloocan | D5: jcamores@chookstogoinc.com.ph | E5: jcamores@chookstogoinc.com.ph | F5: Bounty2025
A6: Gim San Tiu | B6: BGC | C6: Brixton and Central Luzon | D6: gctiu@chookstogoinc.com.ph | E6: gctiu@chookstogoinc.com.ph | F6: Bounty2025
A7: Gwyn Kyle Tarayo | B7: Crossing Calamba | C7: Southern Tagalog (CALABARZON and Bicol) | D7: gbtarayo@chookstogoinc.com.ph | E7: gbtarayo@chookstogoinc.com.ph | F7: Bounty2025
A8: John Lloyd Paculan | B8: Lawa | C8: Laguna and Cavite | D8: jlpaculan@chookstogoinc.com.ph | E8: jlpaculan@chookstogoinc.com.ph | F8: Bounty2025
A9: John Bennedick Amposta | B9: Batangas | C9: Batangas | D9: jpamposta@choockstogoinc.com.ph | E9: jpamposta@choockstogoinc.com.ph | F9: Bounty2025
A10: John Lawrence Cruzada | B10: Bicol | C10: Bicol | D10: jcrcruzada@chookstogoinc.com.ph | E10: jcrcruzada@chookstogoinc.com.ph | F10: Bounty2025
A11: Sherwin Jalon | B11: Zamboanga | C11: Zamboanga and Visayas (Cebu, Dumaguete, Bacolod, Iloilo, Roxas, Tacloban, Ormoc, and Calbayog) | D11: swjalon@chookstogoinc.com.ph | E11: swjalon@chookstogoinc.com.ph | F11: Bounty2025
A12: Sergio Marcellana Jr. | B12: Cebu | C12: Cebu and Ormoc | D12: simarcellana@chookstogoinc.com.ph | E12: simarcellana@chookstogoinc.com.ph | F12: Bounty2025
... A18: Sonny Ian Betarmos | B18: Davao | C18: Davao and Ozamis | D18: sgbetarmos@chookstogoinc.com.ph | E18: sgbetarmos@chookstogoinc.com.ph | F18: Bounty2025
